<?xml version="1.0"?>
<robot xmlns:xacro="http://www.ros.org/wiki/xacro" name="spider">

  <xacro:property name="base_r"        value="0.12"/>
  <xacro:property name="base_h"        value="0.01"/>
  <xacro:property name="dome_r"        value="0.1"/>
  <xacro:property name="dome_z"        value="${base_h / 2.0}"/>
  <xacro:property name="hip_r"         value="${base_r - 0.015}"/>
  <xacro:property name="hip_z_offset"  value="${base_h / 2.0}"/>

  <xacro:property name="coxa_r"  value="0.018"/>
  <xacro:property name="coxa_l"  value="0.045"/>
  <xacro:property name="femur_r" value="0.014"/>
  <xacro:property name="femur_l" value="0.10"/>
  <xacro:property name="tibia_r" value="0.012"/>
  <xacro:property name="tibia_l" value="0.13"/>

  <xacro:property name="base_mass"  value="1.5"/>
  <xacro:property name="coxa_mass"  value="0.06"/>
  <xacro:property name="femur_mass" value="0.12"/>
  <xacro:property name="tibia_mass" value="0.08"/>

  <xacro:macro name="sphere_inertia" params="m r">
    <inertial>
      <origin xyz="0 0 0" rpy="0 0 0"/>
      <mass value="${m}"/>
      <inertia ixx="${2.0/5.0 * m * r * r}" iyy="${2.0/5.0 * m * r * r}" izz="${2.0/5.0 * m * r * r}" ixy="0" ixz="0" iyz="0"/>
    </inertial>
  </xacro:macro>

  <xacro:macro name="cylinder_inertia" params="m r l">
    <inertial>
      <origin xyz="0 0 0" rpy="0 0 0"/>
      <mass value="${m}"/>
      <inertia ixx="${m * (3*r*r + l*l) / 12.0}" iyy="${m * (3*r*r + l*l) / 12.0}" izz="${m * r * r / 2.0}" ixy="0" ixz="0" iyz="0"/>
    </inertial>
  </xacro:macro>

  <xacro:macro name="base_link_inertia">
    <inertial>
      <origin xyz="0 0 0" rpy="0 0 0"/>
      <mass value="${base_mass}"/>
      <inertia ixx="${base_mass * (3*base_r*base_r + base_h*base_h) / 12.0}" iyy="${base_mass * (3*base_r*base_r + base_h*base_h) / 12.0}" izz="${base_mass * base_r*base_r / 2.0}" ixy="0" ixz="0" iyz="0"/>
    </inertial>
  </xacro:macro>

  <xacro:macro name="leg" params="leg_name hip_x hip_y hip_yaw">

    <link name="${leg_name}_coxa_link">
      <inertial>
        <origin xyz="${coxa_l/2} 0 0" rpy="0 0 0"/>
        <mass value="${coxa_mass}"/>
        <inertia ixx="${coxa_mass * coxa_r*coxa_r / 2.0}" iyy="${coxa_mass * (3*coxa_r*coxa_r + coxa_l*coxa_l) / 12.0}" izz="${coxa_mass * (3*coxa_r*coxa_r + coxa_l*coxa_l) / 12.0}" ixy="0" ixz="0" iyz="0"/>
      </inertial>
      <visual>
        <origin xyz="${coxa_l/2} 0 0" rpy="0 ${pi/2} 0"/>
        <geometry><cylinder radius="${coxa_r}" length="${coxa_l}"/></geometry>
        <material name="servo_blue"><color rgba="0.2 0.35 0.75 1.0"/></material>
      </visual>
      <collision>
        <origin xyz="${coxa_l/2} 0 0" rpy="0 ${pi/2} 0"/>
        <geometry><cylinder radius="${coxa_r}" length="${coxa_l}"/></geometry>
      </collision>
    </link>

    <joint name="${leg_name}_coxa_joint" type="revolute">
      <parent link="base_link"/>
      <child link="${leg_name}_coxa_link"/>
      <origin xyz="${hip_x} ${hip_y} ${hip_z_offset}" rpy="0 0 ${hip_yaw}"/>
      <axis xyz="0 0 1"/>
      <limit lower="${-pi/2}" upper="${pi/2}" effort="10.0" velocity="3.14"/>
      <dynamics damping="0.1" friction="0.0"/>
    </joint>

    <link name="${leg_name}_femur_link">
      <inertial>
        <origin xyz="${femur_l/2} 0 0" rpy="0 0 0"/>
        <mass value="${femur_mass}"/>
        <inertia ixx="${femur_mass * femur_r*femur_r / 2.0}" iyy="${femur_mass * (3*femur_r*femur_r + femur_l*femur_l) / 12.0}" izz="${femur_mass * (3*femur_r*femur_r + femur_l*femur_l) / 12.0}" ixy="0" ixz="0" iyz="0"/>
      </inertial>
      <visual>
        <origin xyz="${femur_l/2} 0 0" rpy="0 ${pi/2} 0"/>
        <geometry><cylinder radius="${femur_r}" length="${femur_l}"/></geometry>
        <material name="link_wood"><color rgba="0.75 0.60 0.35 1.0"/></material>
      </visual>
      <collision>
        <origin xyz="${femur_l/2} 0 0" rpy="0 ${pi/2} 0"/>
        <geometry><cylinder radius="${femur_r}" length="${femur_l}"/></geometry>
      </collision>
    </link>

    <joint name="${leg_name}_femur_joint" type="revolute">
      <parent link="${leg_name}_coxa_link"/>
      <child link="${leg_name}_femur_link"/>
      <origin xyz="${coxa_l} 0 0" rpy="0 ${-pi/6} 0"/>
      <axis xyz="0 1 0"/>
      <limit lower="${-pi/3}" upper="${pi/3}" effort="10.0" velocity="3.14"/>
      <dynamics damping="0.1" friction="0.0"/>
    </joint>

    <link name="${leg_name}_tibia_link">
      <inertial>
        <origin xyz="${tibia_l/2} 0 0" rpy="0 0 0"/>
        <mass value="${tibia_mass}"/>
        <inertia ixx="${tibia_mass * tibia_r*tibia_r / 2.0}" iyy="${tibia_mass * (3*tibia_r*tibia_r + tibia_l*tibia_l) / 12.0}" izz="${tibia_mass * (3*tibia_r*tibia_r + tibia_l*tibia_l) / 12.0}" ixy="0" ixz="0" iyz="0"/>
      </inertial>
      <visual>
        <origin xyz="${tibia_l/2} 0 0" rpy="0 ${pi/2} 0"/>
        <geometry><cylinder radius="${tibia_r}" length="${tibia_l}"/></geometry>
        <material name="link_dark"><color rgba="0.25 0.25 0.25 1.0"/></material>
      </visual>
      <collision>
        <origin xyz="${tibia_l/2} 0 0" rpy="0 ${pi/2} 0"/>
        <geometry><cylinder radius="${tibia_r}" length="${tibia_l}"/></geometry>
      </collision>
      <collision>
        <origin xyz="${tibia_l} 0 0" rpy="0 0 0"/>
        <geometry><sphere radius="${tibia_r}"/></geometry>
      </collision>
    </link>

    <joint name="${leg_name}_tibia_joint" type="revolute">
      <parent link="${leg_name}_femur_link"/>
      <child link="${leg_name}_tibia_link"/>
      <origin xyz="${femur_l} 0 0" rpy="0 ${pi/4} 0"/>
      <axis xyz="0 1 0"/>
      <limit lower="${-pi/2}" upper="${pi/2}" effort="10.0" velocity="3.14"/>
      <dynamics damping="0.1" friction="0.0"/>
    </joint>

    <transmission name="${leg_name}_coxa_trans"><type>transmission_interface/SimpleTransmission</type><joint name="${leg_name}_coxa_joint"><hardwareInterface>hardware_interface/PositionJointInterface</hardwareInterface></joint><actuator name="${leg_name}_coxa_joint_motor"><hardwareInterface>hardware_interface/PositionJointInterface</hardwareInterface><mechanicalReduction>1</mechanicalReduction></actuator></transmission>
    <transmission name="${leg_name}_femur_trans"><type>transmission_interface/SimpleTransmission</type><joint name="${leg_name}_femur_joint"><hardwareInterface>hardware_interface/PositionJointInterface</hardwareInterface></joint><actuator name="${leg_name}_femur_joint_motor"><hardwareInterface>hardware_interface/PositionJointInterface</hardwareInterface><mechanicalReduction>1</mechanicalReduction></actuator></transmission>
    <transmission name="${leg_name}_tibia_trans"><type>transmission_interface/SimpleTransmission</type><joint name="${leg_name}_tibia_joint"><hardwareInterface>hardware_interface/PositionJointInterface</hardwareInterface></joint><actuator name="${leg_name}_tibia_joint_motor"><hardwareInterface>hardware_interface/PositionJointInterface</hardwareInterface><mechanicalReduction>1</mechanicalReduction></actuator></transmission>

  </xacro:macro>

  <link name="base_footprint"/>
  <joint name="base_footprint_joint" type="fixed">
    <parent link="base_footprint"/>
    <child link="base_link"/>
    <origin xyz="0 0 0.30" rpy="0 0 0"/>
  </joint>

  <link name="base_link">
    <xacro:base_link_inertia/>
    <visual>
      <origin xyz="0 0 0" rpy="0 0 0"/>
      <geometry><cylinder radius="${base_r}" length="${base_h}"/></geometry>
      <material name="chassis_dark"><color rgba="0.18 0.18 0.20 1.0"/></material>
    </visual>
    <visual>
      <origin xyz="0 0 ${dome_z}" rpy="0 0 0"/>
      <geometry><mesh filename="package://spider_description/meshes/dome.obj"/></geometry>
      <material name="chassis_orange"><color rgba="0.85 0.35 0.05 1.0"/></material>
    </visual>
    <collision>
      <origin xyz="0 0 0" rpy="0 0 0"/>
      <geometry><cylinder radius="${base_r}" length="${base_h}"/></geometry>
    </collision>
    <collision>
      <origin xyz="0 0 ${dome_z + dome_r/2.0}" rpy="0 0 0"/>
      <geometry><cylinder radius="${dome_r}" length="${dome_r}"/></geometry>
    </collision>
  </link>

  <xacro:leg leg_name="front_right" hip_x="${hip_r * 0.70711}"  hip_y="${hip_r * 0.70711}" hip_yaw="${pi/4}"/>
  <xacro:leg leg_name="front_left"  hip_x="${-hip_r * 0.70711}" hip_y="${hip_r * 0.70711}" hip_yaw="${3*pi/4}"/>
  <xacro:leg leg_name="back_left"   hip_x="${-hip_r * 0.70711}" hip_y="${-hip_r * 0.70711}" hip_yaw="${-3*pi/4}"/>
  <xacro:leg leg_name="back_right"  hip_x="${hip_r * 0.70711}"  hip_y="${-hip_r * 0.70711}" hip_yaw="${-pi/4}"/>

  <ros2_control name="spider_ign_ros2_control" type="system">
    <hardware>
      <plugin>ign_ros2_control/IgnitionSystem</plugin>
    </hardware>

    <xacro:macro name="leg_control" params="prefix">
      <joint name="${prefix}_coxa_joint">
        <command_interface name="position"><param name="min">${-pi/2}</param><param name="max">${pi/2}</param></command_interface>
        <state_interface name="position"/><state_interface name="velocity"/>
      </joint>
      <joint name="${prefix}_femur_joint">
        <command_interface name="position"><param name="min">${-pi/3}</param><param name="max">${pi/3}</param></command_interface>
        <state_interface name="position"/><state_interface name="velocity"/>
      </joint>
      <joint name="${prefix}_tibia_joint">
        <command_interface name="position">
          <param name="min">${-pi/2}</param>
          <param name="max">${pi/2}</param>
        </command_interface>
        <state_interface name="position"/><state_interface name="velocity"/>
      </joint>
    </xacro:macro>

    <xacro:leg_control prefix="front_right"/>
    <xacro:leg_control prefix="front_left"/>
    <xacro:leg_control prefix="back_left"/>
    <xacro:leg_control prefix="back_right"/>

  </ros2_control>

  <gazebo>
    <plugin filename="libign_ros2_control-system.so" name="ign_ros2_control::IgnitionROS2ControlPlugin">
      <parameters>$(find spider_description)/config/controllers.yaml</parameters>
      <ros><remapping>/controller_manager/robot_description:=/robot_description</remapping></ros>
    </plugin>
  </gazebo>

</robot>